<?xml version="1.0" encoding="utf-8"?>
<!-- This URDF was automatically created by SolidWorks to URDF Exporter! Originally created by Stephen Brawner (brawner@gmail.com) -->
<robot name="arm_description">

  <link name="base_link">
    <inertial>
      <origin xyz="0 0 0" rpy="0 0 0"/>
      <mass value="1.0"/>
      <inertia ixx="0.1" ixy="0.0" ixz="0.0"
               iyy="0.1" iyz="0.0"
               izz="0.1"/>
    </inertial>

    <visual>
      <origin xyz="0 0 0" rpy="0 0 0"/>
      <geometry>
        <mesh filename="model://arm_description/meshes/base_link.STL"/>
      </geometry>
      <material name="">
        <color rgba="0.89804 0.91765 0.92941 1"/>
      </material>
    </visual>

    <collision>
      <origin xyz="0 0 0" rpy="0 0 0"/>
      <geometry>
        <mesh filename="model://arm_description/meshes/base_link.STL"/>
      </geometry>
    </collision>

    <collision>
      <origin xyz="0 0 0" rpy="0 0 0"/>
      <geometry>
        <box size="0.5 0.5 0.1"/>
      </geometry>
    </collision>
  </link>

  <link name="link_1">
    <inertial>
      <origin xyz="9.422E-11 0.021256 1.8368E-08" rpy="0 0 0"/>
      <mass value="0.80448"/>
      <inertia ixx="0.0018112" ixy="-4.2512E-12" ixz="-5.3857E-13"
               iyy="0.0019297" iyz="-9.5135E-10"
               izz="0.0012455"/>
    </inertial>
    <visual>
      <origin xyz="0 0 0" rpy="0 0 0"/>
      <geometry>
        <mesh filename="model://arm_description/meshes/link_1.STL"/>
      </geometry>
      <material name="">
        <color rgba="0.89804 0.91765 0.92941 1"/>
      </material>
    </visual>
    <collision>
      <origin xyz="0 0 0" rpy="0 0 0"/>
      <geometry>
        <mesh filename="model://arm_description/meshes/link_1.STL"/>
      </geometry>
    </collision>
  </link>

  <joint name="joint_1" type="revolute">
    <origin xyz="0.085752 -0.24683 0.16947" rpy="1.5708 0 -1.8982"/>
    <parent link="base_link"/>
    <child link="link_1"/>
    <axis xyz="0 1 0"/>
    <limit lower="0" upper="3.142" effort="8" velocity="0.5"/>
  </joint>

  <link name="link_2">
    <inertial>
      <origin xyz="-1.8319E-15 0.19998 -4.8295E-14" rpy="0 0 0"/>
      <mass value="0.37385"/>
      <inertia ixx="0.0083547" ixy="-1.0706E-18" ixz="1.6263E-19"
               iyy="0.00024181" iyz="2.3477E-05"
               izz="0.0081135"/>
    </inertial>
    <visual>
      <origin xyz="0 0 0" rpy="0 0 0"/>
      <geometry>
        <mesh filename="model://arm_description/meshes/link_2.STL"/>
      </geometry>
      <material name="">
        <color rgba="0.89804 0.91765 0.92941 1"/>
      </material>
    </visual>
    <collision>
      <origin xyz="0 0 0" rpy="0 0 0"/>
      <geometry>
        <mesh filename="model://arm_description/meshes/link_2.STL"/>
      </geometry>
    </collision>
  </link>

  <joint name="joint_2" type="revolute">
    <origin xyz="0 0.09 0" rpy="1.8112 -1.5708 0"/>
    <parent link="link_1"/>
    <child link="link_2"/>
    <axis xyz="1 0 0"/>
    <limit lower="30" upper="1.308" effort="110" velocity="0.5"/>
  </joint>

  <link name="link_3">
    <inertial>
      <origin xyz="-3.7748E-15 -0.2244 -1.2046E-13" rpy="0 0 0"/>
      <mass value="0.44246"/>
      <inertia ixx="0.012149" ixy="-1.7313E-17" ixz="-2.7105E-19"
               iyy="0.00032049" iyz="2.7704E-05"
               izz="0.011829"/>
    </inertial>
    <visual>
      <origin xyz="0 0 0" rpy="0 0 0"/>
      <geometry>
        <mesh filename="model://arm_description/meshes/link_3.STL"/>
      </geometry>
      <material name="">
        <color rgba="0.89804 0.91765 0.92941 1"/>
      </material>
    </visual>
    <collision>
      <origin xyz="0 0 0" rpy="0 0 0"/>
      <geometry>
        <mesh filename="model://arm_description/meshes/link_3.STL"/>
      </geometry>
    </collision>
  </link>

  <joint name="joint_3" type="revolute">
    <origin xyz="0 0.4 0" rpy="3.1357 0 0"/>
    <parent link="link_2"/>
    <child link="link_3"/>
    <axis xyz="1 0 0"/>
    <limit lower="30" upper="3.142" effort="37" velocity="0.5"/>
  </joint>

  <link name="link_4">
    <inertial>
      <origin xyz="-3.4472E-14 -0.035205 -1.3045E-15" rpy="0 0 0"/>
      <mass value="0.42165"/>
      <inertia ixx="0.00044604" ixy="3.9302E-19" ixz="6.0986E-19"
               iyy="0.00024958" iyz="-2.1006E-19"
               izz="0.00024139"/>
    </inertial>
    <visual>
      <origin xyz="0 0 0" rpy="0 0 0"/>
      <geometry>
        <mesh filename="model://arm_description/meshes/link_4.STL"/>
      </geometry>
      <material name="">
        <color rgba="0.89804 0.91765 0.92941 1"/>
      </material>
    </visual>
    <collision>
      <origin xyz="0 0 0" rpy="0 0 0"/>
      <geometry>
        <mesh filename="model://arm_description/meshes/link_4.STL"/>
      </geometry>
    </collision>
  </link>

  <joint name="joint_4" type="continuous">
    <origin xyz="0 -0.45 0" rpy="1.5708 0.59916 -1.5708"/>
    <parent link="link_3"/>
    <child link="link_4"/>
    <axis xyz="0 0 1"/>
    <limit lower="0" upper="3.142" effort="3" velocity="0.5"/>
  </joint>

  <link name="end_effector">
    <inertial>
      <origin xyz="-3.783E-05 -0.027974 -2.387E-15" rpy="0 0 0"/>
      <mass value="0.17882"/>
      <inertia ixx="0.00013157" ixy="-4.6641E-07" ixz="5.8106E-19"
               iyy="0.00021828" iyz="-5.7969E-20"
               izz="0.00034322"/>
    </inertial>
    <visual>
      <origin xyz="0 0 0" rpy="0 0 0"/>
      <geometry>
        <mesh filename="model://arm_description/meshes/end_effector.STL"/>
      </geometry>
      <material name="">
        <color rgba="0.89804 0.91765 0.92941 1"/>
      </material>
    </visual>
    <collision>
      <origin xyz="0 0 0" rpy="0 0 0"/>
      <geometry>
        <mesh filename="model://arm_description/meshes/end_effector.STL"/>
      </geometry>
    </collision>
  </link>

  <joint name="joint_5" type="revolute">
    <origin xyz="0 -0.087206 0" rpy="0 0.35801 0"/>
    <parent link="link_4"/>
    <child link="end_effector"/>
    <axis xyz="0 1 0"/>
    <limit lower="0" upper="3.142" effort="3" velocity="0.5"/>
  </joint>

</robot>
